Workbook

Sheet Start Here
A1: KLR Trading Practice Plan: Start Here
A2: Built for an 8-week MT5 demo practice period. Times in WAT (UTC+1).
A4: Tabs
A5: Trading Plan | B5: The full written plan: markets, session times, strategy, risk rules, schedule. Read it once a week.
A6: Checklist | B6: A printable one-page checklist. Use one copy per session.
A7: Dashboard | B7: Automatic stats, go-live criteria, breakdowns and mistake tracker.
A8: Journal | B8: Log every trade here, straight after the session.
A9: Daily Log | B9: One row per weekday: attendance, prep, mood, lesson. Fill it even on no-trade days.
A10: Weekly Review | B10: Friday review: automatic weekly stats, your reflections and charts.
A11: Settings | B11: Start date, balance, risk %, limits, go-live thresholds, position size calculator, dropdown lists.
A13: Colour legend
A14: Yellow cell | B14: You type here (blue text). Use the dropdowns where offered.
A15: Grey cell | B15: Calculates automatically. Don't type over it.
A17: Daily workflow
A18: Step 1 | B18: Print the Checklist (or keep it open) and do the 10-minute prep.
A19: Step 2 | B19: Trade the window. Only take trades that meet all 5 checks.
A20: Step 3 | B20: Straight after: log trades in the Journal and fill the Daily Log row.
A21: Step 4 | B21: Friday: fill the Weekly Review and read the Dashboard.
A23: Example Journal row (what a filled-in trade looks like)
A24: Field | B24: Example value
A25: Date | B25: 12-Oct-26
A26: Session | B26: New York
A27: Instrument | B27: US500
A28: Direction | B28: Short
A29: Zone type | B29: Prev Day High
A30: Checks 1-5 | B30: Y Y Y Y Y
A31: Entry time | B31: 14:42
A32: Entry | B32: 6712.50
A33: Stop | B33: 6716.00
A34: Target (auto) | B34: 6702.00
A35: Exit | B35: 6702.00
... A41: Notes | B41: Waited for LH + trigger candle under yesterday's high. Moved to BE at +1.5R.
A43: Price levels in the example are illustrative only.
A45: Key dates
A46: Sat 10 - Sun 11 Oct | B46: Week 0: platform setup and bar-replay practice (20 setups per instrument).
A47: Mon 12 Oct | B47: Week 1 starts (Phase 1: Execution).
A48: Mon 26 Oct | B48: UK clocks changed: London session now 09:00-09:45 WAT.
A49: Mon 2 Nov | B49: US clocks changed: New York session now 15:30-16:15 WAT.
A50: Fri 6 Nov | B50: Week 4 review: the only allowed rule change (v1.1).
A51: Fri 4 Dec | B51: Week 8 review: go-live decision on the Dashboard.

Sheet Trading Plan
A1: Trading Plan: Key-Level Reversal (KLR) v1.0
A2: 8-week demo practice plan, adapted from the 'start trading with $4' video. Trader time zone: WAT (UTC+1).
A4: 1. Purpose
A5: • | B5: Prove over 8 weeks that I can follow ONE scalping strategy without changing it, and find out whether it has positive expectancy.
A6: • | B6: Results in Weeks 1-2 do not matter. Showing up, following the rules and logging every trade do.
A7: • | B7: Success = go-live criteria met on the Dashboard: 40+ trades, 90%+ rule adherence, expectancy ≥ +0.25R, PF ≥ 1.3, max DD ≤ 10R, 90%+ attendance.
A9: 2. Markets, platform & sessions
A10: • | B10: Platform: MT5 demo for execution; TradingView for marking levels, replay and screenshots. Crypto (Bybit/MEXC) is parked for these 8 weeks.
A11: • | B11: Session A, London open: XAUUSD. Prep 07:50, trade 08:00-08:45 WAT, journal by 08:50. From Mon 26 Oct 2026 (UK clocks change) it's one hour later: prep 08:50, trade 09:00-09:45.
A12: • | B12: Session B, New York open: US500. Prep 14:20, trade 14:30-15:15 WAT, journal by 15:20. From Mon 2 Nov 2026 (US clocks change) it's one hour later: prep 15:20, trade 15:30-16:15.
A13: • | B13: Total time: about 2 x 60 minutes per weekday. No trading on weekends; weekends are for review only.
A14: • | B14: Why these two: you already know gold and indices, US500 tracks the same S&P 500 the video trades, and both move hard at their session open.
A16: 3. Timeframes
A17: • | B17: 15-minute (plus 1-hour for clustered S/R): big-picture trend and key zones, marked BEFORE the session.
A18: • | B18: 1-minute: structure shift, trigger candle and entry. No indicators; read price swings only.
A20: 4. Pre-session prep (10 minutes)
A21: • | B21: Check the economic calendar (e.g. ForexFactory) for red-folder USD news during the window. Note the times.
A22: • | B22: Mark zones: previous day high/low, current session range (Asian range for London; London high/low for NY), and the 2-3 strongest clustered S/R zones on 1H/15m.
A23: • | B23: Write one line of bias: is the 15m trending up, down or ranging? Which zones are reversal candidates?
A24: • | B24: Set price alerts at the zones, so you don't have to stare at every tick.
A25: • | B25: State check: if your emotion is 5 (angry, anxious, tired), skip the session and log it as not attended.
A27: 5. Entry checklist (all 5 must be YES)
A28: • | B28: Described for a SHORT at resistance. A LONG at support is the exact mirror.
A29: • | B29: 1 LEVEL: price trades into a zone marked during prep. No drawing new levels mid-session.
A30: • | B30: 2 EXTENSION: on 1m, price arrives with a clear run (at least 3 consecutive higher highs and higher lows into the zone). No run means nothing to reverse, so no trade.
A31: • | B31: 3 SHIFT: price breaks the latest 1m higher low (makes a lower low), then forms a lower high below the zone extreme.
A32: • | B32: 4 TRIGGER: a strong bearish candle (body ≥ 60% of its range) forms off the lower high. Place a sell-stop just below its low; you enter only on the break.
A33: • | B33: 5 ROOM: stop above the lower high or zone extreme, whichever is higher, plus spread. Next opposing zone at least 3R away. Spread ≤ 10% of stop distance. No red news within 15 minutes.
A34: • | B34: If any answer is NO or 'kind of': no trade. Missing a trade costs nothing; a bad trade costs R.
A36: 6. Trade management
A37: • | B37: Size every trade with the calculator on the Settings tab so the stop = exactly 0.5% of balance (1R).
A38: • | B38: Target: fixed 3R (1:3 risk-reward). Break-even needs a 25% win rate; 30% or more is profitable.
A39: • | B39: Break-even: when price reaches +1.5R, move the stop to entry.
A40: • | B40: Time stop: if the trade hasn't hit target, stop or break-even within 30 minutes of entry, close it at market and log it as 'Time stop'.
A41: • | B41: Never widen a stop, never add to a position, never close early out of fear. No trailing stops during practice; that can be tested at the Week 4 review.
A42: • | B42: Take a screenshot at entry and at exit (TradingView), then paste the link into the Journal.
A44: 7. Risk rules (non-negotiable)
A45: • | B45: Risk 0.5% per trade. One open position at a time.
A46: • | B46: Max 2 trades per session, max 3 trades per day. After 2 losses in a day, you're done for the day.
A47: • | B47: Weekly loss limit -5R: if it's hit, stop trading for the rest of the week and do the review early.
...

Sheet Checklist
A1: Daily Checklist: print it and keep it next to your screen
A2: One copy per session. Tick each box. Any unticked entry box = NO TRADE.
A4: BEFORE THE SESSION (10 min)
A5: ☐ | B5: Red-folder USD news checked. Times: ____________
A6: ☐ | B6: Previous day high / low marked
A7: ☐ | B7: Session range marked (Asian range for London / London high-low for NY)
A8: ☐ | B8: 2-3 clustered S/R zones on 1H / 15m marked
A9: ☐ | B9: 15m bias written: UP / DOWN / RANGE
A10: ☐ | B10: Alerts set at zones
A11: ☐ | B11: Emotion check (1-5): ____ 5 = skip the session
A13: ENTRY: ALL 5 OR NO TRADE
A14: ☐ | B14: 1 LEVEL: price is in a zone marked BEFORE the session
A15: ☐ | B15: 2 EXTENSION: clear 1m run into the zone (3+ HH/HL for a short, LL/LH for a long)
A16: ☐ | B16: 3 SHIFT: 1m structure broke (LL then LH for a short / HH then HL for a long)
A17: ☐ | B17: 4 TRIGGER: strong candle (body ≥ 60%); enter on the break of its low/high
A18: ☐ | B18: 5 ROOM: stop beyond the swing + spread, next zone ≥ 3R away, spread ≤ 10% of stop, no red news within 15 min
A20: ONCE IN THE TRADE
A21: ☐ | B21: Lot size from calculator = 0.5% risk (1R)
A22: ☐ | B22: Stop and 3R target placed immediately
A23: ☐ | B23: At +1.5R: stop moved to entry (break-even)
A24: ☐ | B24: 30 minutes with no result: close at market (time stop)
A25: ☐ | B25: Screenshot taken at entry and exit
A27: LIMITS
A28: ☐ | B28: Max 2 trades this session, max 3 today
A29: ☐ | B29: 2 losses today = done for the day
A30: ☐ | B30: Week at -5R = done for the week
A31: ☐ | B31: Window over = platform closed
A33: AFTER THE SESSION (5 min)
A34: ☐ | B34: Every trade logged in Journal (honest mistake tag)
A35: ☐ | B35: Daily Log row filled (attendance, prep, mood, lesson)
B37: Date: ___________ Session: London / New York Trades: ___ Result: ____ R

Sheet Dashboard
A1: Practice Dashboard
A2: Everything here is automatic. Read it during your Friday review.
A4: Overall performance | D4: Go-live criteria (check at end of Week 8) | J4: Mistake tracker
A5: Trades logged | B5: =COUNT(Journal!$B$5:$B$304) -> 0 | D5: Criterion | E5: Target | F5: Actual | G5: Status | J5: Mistake | K5: Count | L5: R from these trades
A6: Closed trades | B6: =COUNT(Journal!$T$5:$T$304) -> 0 | D6: Closed trades | E6: =Settings!$B$13 -> 40 | F6: =B6 -> 0 | G6: =IF(F6>=E6,"PASS","NOT YET") -> NOT YET | J6: Entered before trigger | K6: =COUNTIF(Journal!$AD$5:$AD$304,J6) -> 0 | L6: =SUMIFS(Journal!$T$5:$T$304,Journal!$AD$5:$AD$304,J6) -> 0
A7: Wins / Losses / BE | B7: =COUNTIF(Journal!$U$5:$U$304,"Win")&" / "&COUNTIF(Journal!$U$5:$U$304,"Loss")&" / "&COUNTIF(Journal!$U$5:$U$304,"BE") -> 0 / 0 / 0 | D7: Rule adherence | E7: =Settings!$B$14 -> 0.9 | F7: =B19 -> 0 | G7: =IF(F7>=E7,"PASS","NOT YET") -> NOT YET | J7: Level not pre-marked | K7: =COUNTIF(Journal!$AD$5:$AD$304,J7) -> 0 | L7: =SUMIFS(Journal!$T$5:$T$304,Journal!$AD$5:$AD$304,J7) -> 0
A8: Win rate | B8: =IFERROR(COUNTIF(Journal!$U$5:$U$304,"Win")/B6,0) -> 0 | D8: Expectancy (R/trade) | E8: =Settings!$B$15 -> 0.25 | F8: =B11 -> 0 | G8: =IF(F8>=E8,"PASS","NOT YET") -> NOT YET | J8: Moved stop further | K8: =COUNTIF(Journal!$AD$5:$AD$304,J8) -> 0 | L8: =SUMIFS(Journal!$T$5:$T$304,Journal!$AD$5:$AD$304,J8) -> 0
A9: Average win (R) | B9: =IFERROR(AVERAGEIF(Journal!$U$5:$U$304,"Win",Journal!$T$5:$T$304),0) -> 0 | D9: Profit factor | E9: =Settings!$B$16 -> 1.3 | F9: =B13 -> 0 | G9: =IF(F9>=E9,"PASS","NOT YET") -> NOT YET | J9: Closed early (fear) | K9: =COUNTIF(Journal!$AD$5:$AD$304,J9) -> 0 | L9: =SUMIFS(Journal!$T$5:$T$304,Journal!$AD$5:$AD$304,J9) -> 0
A10: Average loss (R) | B10: =IFERROR(AVERAGEIF(Journal!$U$5:$U$304,"Loss",Journal!$T$5:$T$304),0) -> 0 | D10: Max drawdown (R, max allowed) | E10: =Settings!$B$17 -> 10 | F10: =ABS(B14) -> 0 | G10: =IF(F10<=E10,"PASS","NOT YET") -> PASS | J10: Chased / FOMO | K10: =COUNTIF(Journal!$AD$5:$AD$304,J10) -> 0 | L10: =SUMIFS(Journal!$T$5:$T$304,Journal!$AD$5:$AD$304,J10) -> 0
A11: Expectancy (R per trade) | B11: =IFERROR(AVERAGE(Journal!$T$5:$T$304),0) -> 0 | D11: Session attendance | E11: =Settings!$B$18 -> 0.9 | F11: =B22 -> 0 | G11: =IF(F11>=E11,"PASS","NOT YET") -> NOT YET | J11: Outside session window | K11: =COUNTIF(Journal!$AD$5:$AD$304,J11) -> 0 | L11: =SUMIFS(Journal!$T$5:$T$304,Journal!$AD$5:$AD$304,J11) -> 0
A12: Total R | B12: =SUM(Journal!$T$5:$T$304) -> 0 | J12: Over max trades | K12: =COUNTIF(Journal!$AD$5:$AD$304,J12) -> 0 | L12: =SUMIFS(Journal!$T$5:$T$304,Journal!$AD$5:$AD$304,J12) -> 0
A13: Profit factor | B13: =IFERROR(SUMIF(Journal!$T$5:$T$304,">0")/ABS(SUMIF(Journal!$T$5:$T$304,"<0")),0) -> 0 | D13: Verdict | E13: =IF(COUNTIF(G6:G11,"PASS")=6,"READY for controlled live trading","KEEP PRACTISING - fix the biggest leak first") -> KEEP PRACTISING - fix the biggest leak first | J13: Revenge trade | K13: =COUNTIF(Journal!$AD$5:$AD$304,J13) -> 0 | L13: =SUMIFS(Journal!$T$5:$T$304,Journal!$AD$5:$AD$304,J13) -> 0
A14: Max drawdown (R) | B14: =MIN(Journal!$AB$5:$AB$304) -> 0 | J14: Traded through news | K14: =COUNTIF(Journal!$AD$5:$AD$304,J14) -> 0 | L14: =SUMIFS(Journal!$T$5:$T$304,Journal!$AD$5:$AD$304,J14) -> 0
A15: Longest losing streak | B15: =MAX(Journal!$AC$5:$AC$304) -> 0 | D15: By Instrument | J15: Wrong position size | K15: =COUNTIF(Journal!$AD$5:$AD$304,J15) -> 0 | L15: =SUMIFS(Journal!$T$5:$T$304,Journal!$AD$5:$AD$304,J15) -> 0
A16: Net P&L ($, demo) | B16: =SUM(Journal!$X$5:$X$304) -> 0 | D16: Instrument | E16: Trades | F16: Win rate | G16: Total R | H16: Expectancy
A17: Current balance ($) | B17: =Settings!$B$5+SUM(Journal!$X$5:$X$304) -> 1000 | D17: XAUUSD | E17: =COUNTIFS(Journal!$E$5:$E$304,D17,Journal!$T$5:$T$304,">-9999") -> 0 | F17: =IFERROR(COUNTIFS(Journal!$E$5:$E$304,D17,Journal!$U$5:$U$304,"Win")/E17,0) -> 0 | G17: =SUMIFS(Journal!$T$5:$T$304,Journal!$E$5:$E$304,D17) -> 0 | H17: =IFERROR(G17/E17,0) -> 0 | J17: Your biggest leak is the mistake with the highest count. Fix that one first.
A18: Return on start balance | B18: =IFERROR(SUM(Journal!$X$5:$X$304)/Settings!$B$5,0) -> 0 | D18: US500 | E18: =COUNTIFS(Journal!$E$5:$E$304,D18,Journal!$T$5:$T$304,">-9999") -> 0 | F18: =IFERROR(COUNTIFS(Journal!$E$5:$E$304,D18,Journal!$U$5:$U$304,"Win")/E18,0) -> 0 | G18: =SUMIFS(Journal!$T$5:$T$304,Journal!$E$5:$E$304,D18) -> 0 | H18: =IFERROR(G18/E18,0) -> 0
A19: Rule adherence | B19: =IFERROR(COUNTIF(Journal!$AE$5:$AE$304,"Yes")/B5,0) -> 0
A20: Expectancy: rule-compliant trades | B20: =IFERROR(AVERAGEIFS(Journal!$T$5:$T$304,Journal!$AE$5:$AE$304,"Yes"),0) -> 0 | D20: By Session
A21: Expectancy: rule-breaking trades | B21: =IFERROR(AVERAGEIFS(Journal!$T$5:$T$304,Journal!$AE$5:$AE$304,"No"),0) -> 0 | D21: Session | E21: Trades | F21: Win rate | G21: Total R | H21: Expectancy
A22: Session attendance (to date) | B22: =IFERROR((COUNTIF('Daily Log'!$C$5:$C$64,"Y")+COUNTIF('Daily Log'!$D$5:$D$64,"Y"))/(2*COUNTIF('Daily Log'!$A$5:$A$64,"<="&TODAY())),0) -> 0 | D22: London | E22: =COUNTIFS(Journal!$D$5:$D$304,D22,Journal!$T$5:$T$304,">-9999") -> 0 | F22: =IFERROR(COUNTIFS(Journal!$D$5:$D$304,D22,Journal!$U$5:$U$304,"Win")/E22,0) -> 0 | G22: =SUMIFS(Journal!$T$5:$T$304,Journal!$D$5:$D$304,D22) -> 0 | H22: =IFERROR(G22/E22,0) -> 0
D23: New York | E23: =COUNTIFS(Journal!$D$5:$D$304,D23,Journal!$T$5:$T$304,">-9999") -> 0 | F23: =IFERROR(COUNTIFS(Journal!$D$5:$D$304,D23,Journal!$U$5:$U$304,"Win")/E23,0) -> 0 | G23: =SUMIFS(Journal!$T$5:$T$304,Journal!$D$5:$D$304,D23) -> 0 | H23: =IFERROR(G23/E23,0) -> 0
D25: By Direction
D26: Direction | E26: Trades | F26: Win rate | G26: Total R | H26: Expectancy
D27: Long | E27: =COUNTIFS(Journal!$F$5:$F$304,D27,Journal!$T$5:$T$304,">-9999") -> 0 | F27: =IFERROR(COUNTIFS(Journal!$F$5:$F$304,D27,Journal!$U$5:$U$304,"Win")/E27,0) -> 0 | G27: =SUMIFS(Journal!$T$5:$T$304,Journal!$F$5:$F$304,D27) -> 0 | H27: =IFERROR(G27/E27,0) -> 0
D28: Short | E28: =COUNTIFS(Journal!$F$5:$F$304,D28,Journal!$T$5:$T$304,">-9999") -> 0 | F28: =IFERROR(COUNTIFS(Journal!$F$5:$F$304,D28,Journal!$U$5:$U$304,"Win")/E28,0) -> 0 | G28: =SUMIFS(Journal!$T$5:$T$304,Journal!$F$5:$F$304,D28) -> 0 | H28: =IFERROR(G28/E28,0) -> 0
D30: By Zone type
D31: Zone type | E31: Trades | F31: Win rate | G31: Total R | H31: Expectancy
D32: Prev Day High | E32: =COUNTIFS(Journal!$G$5:$G$304,D32,Journal!$T$5:$T$304,">-9999") -> 0 | F32: =IFERROR(COUNTIFS(Journal!$G$5:$G$304,D32,Journal!$U$5:$U$304,"Win")/E32,0) -> 0 | G32: =SUMIFS(Journal!$T$5:$T$304,Journal!$G$5:$G$304,D32) -> 0 | H32: =IFERROR(G32/E32,0) -> 0
D33: Prev Day Low | E33: =COUNTIFS(Journal!$G$5:$G$304,D33,Journal!$T$5:$T$304,">-9999") -> 0 | F33: =IFERROR(COUNTIFS(Journal!$G$5:$G$304,D33,Journal!$U$5:$U$304,"Win")/E33,0) -> 0 | G33: =SUMIFS(Journal!$T$5:$T$304,Journal!$G$5:$G$304,D33) -> 0 | H33: =IFERROR(G33/E33,0) -> 0
D34: Session High | E34: =COUNTIFS(Journal!$G$5:$G$304,D34,Journal!$T$5:$T$304,">-9999") -> 0 | F34: =IFERROR(COUNTIFS(Journal!$G$5:$G$304,D34,Journal!$U$5:$U$304,"Win")/E34,0) -> 0 | G34: =SUMIFS(Journal!$T$5:$T$304,Journal!$G$5:$G$304,D34) -> 0 | H34: =IFERROR(G34/E34,0) -> 0
D35: Session Low | E35: =COUNTIFS(Journal!$G$5:$G$304,D35,Journal!$T$5:$T$304,">-9999") -> 0 | F35: =IFERROR(COUNTIFS(Journal!$G$5:$G$304,D35,Journal!$U$5:$U$304,"Win")/E35,0) -> 0 | G35: =SUMIFS(Journal!$T$5:$T$304,Journal!$G$5:$G$304,D35) -> 0 | H35: =IFERROR(G35/E35,0) -> 0
D36: Clustered S/R | E36: =COUNTIFS(Journal!$G$5:$G$304,D36,Journal!$T$5:$T$304,">-9999") -> 0 | F36: =IFERROR(COUNTIFS(Journal!$G$5:$G$304,D36,Journal!$U$5:$U$304,"Win")/E36,0) -> 0 | G36: =SUMIFS(Journal!$T$5:$T$304,Journal!$G$5:$G$304,D36) -> 0 | H36: =IFERROR(G36/E36,0) -> 0
D37: Round number | E37: =COUNTIFS(Journal!$G$5:$G$304,D37,Journal!$T$5:$T$304,">-9999") -> 0 | F37: =IFERROR(COUNTIFS(Journal!$G$5:$G$304,D37,Journal!$U$5:$U$304,"Win")/E37,0) -> 0 | G37: =SUMIFS(Journal!$T$5:$T$304,Journal!$G$5:$G$304,D37) -> 0 | H37: =IFERROR(G37/E37,0) -> 0

Sheet Journal
A1: Trade Journal
A2: One row per trade. Fill the yellow columns; grey columns calculate automatically. Leave unused rows empty.
A3: Short trade: stop is ABOVE entry. Long trade: stop is BELOW entry. Break-even exit: exit price = entry price. Plan version: type v1.0 (or v1.1 after a Week 4 change).
A4: Trade # | B4: Date | C4: Week | D4: Session | E4: Instrument | F4: Direction | G4: Zone type | H4: 1 Level pre-marked? | I4: 2 Extended move in? | J4: 3 Structure shift? | K4: 4 Trigger candle? | L4: 5 Room ≥3R, spread & news OK? | M4: All 5 met? | N4: Entry time (WAT) | O4: Entry price | P4: Stop loss | Q4: Target (3R) | R4: Exit price | S4: Exit reason | T4: Result (R) | U4: Outcome | V4: Risk % | W4: Risk $ | X4: P&L $ | Y4: Balance $ | Z4: Cumulative R | AA4: Peak R | AB4: Drawdown R | AC4: Loss streak | AD4: Mistake | AE4: Rule-compliant? | AF4: Emotion before (1-5) | AG4: Plan version | AH4: Screenshot link | AI4: Notes / lesson
A5: =IF(B5="","",ROW()-4) | C5: =IF(B5="","",INT((B5-Settings!$B$4)/7)+1) | M5: =IF(B5="","",IF(COUNTIF(H5:L5,"Y")=5,"Yes","No")) | Q5: =IF(OR(O5="",P5=""),"",IF(F5="Long",O5+Settings!$B$7*(O5-P5),O5-Settings!$B$7*(P5-O5))) | T5: =IF(OR(R5="",O5="",P5="",O5=P5),"",ROUND(IF(F5="Long",(R5-O5)/(O5-P5),(O5-R5)/(P5-O5)),2)) | U5: =IF(T5="","",IF(T5>=Settings!$B$20,"Win",IF(T5<=-Settings!$B$20,"Loss","BE"))) | V5: =IF(B5="","",Settings!$B$6) | W5: =IF(B5="","",(Settings!$B$5+SUM(X$4:X4))*V5) | X5: =IF(T5="","",ROUND(T5*W5,2)) | Y5: =IF(T5="","",Settings!$B$5+SUM(X$5:X5)) | Z5: =IF(T5="","",SUM(T$5:T5)) | AA5: =IF(T5="","",MAX(0,MAX(Z$5:Z5))) | AB5: =IF(T5="","",Z5-AA5) | AC5: =IF(U5="","",IF(U5="Loss",N(AC4)+1,0)) | AE5: =IF(B5="","",IF(AND(M5="Yes",OR(AD5="None",AD5="")),"Yes","No"))
A6: =IF(B6="","",ROW()-4) | C6: =IF(B6="","",INT((B6-Settings!$B$4)/7)+1) | M6: =IF(B6="","",IF(COUNTIF(H6:L6,"Y")=5,"Yes","No")) | Q6: =IF(OR(O6="",P6=""),"",IF(F6="Long",O6+Settings!$B$7*(O6-P6),O6-Settings!$B$7*(P6-O6))) | T6: =IF(OR(R6="",O6="",P6="",O6=P6),"",ROUND(IF(F6="Long",(R6-O6)/(O6-P6),(O6-R6)/(P6-O6)),2)) | U6: =IF(T6="","",IF(T6>=Settings!$B$20,"Win",IF(T6<=-Settings!$B$20,"Loss","BE"))) | V6: =IF(B6="","",Settings!$B$6) | W6: =IF(B6="","",(Settings!$B$5+SUM(X$4:X5))*V6) | X6: =IF(T6="","",ROUND(T6*W6,2)) | Y6: =IF(T6="","",Settings!$B$5+SUM(X$5:X6)) | Z6: =IF(T6="","",SUM(T$5:T6)) | AA6: =IF(T6="","",MAX(0,MAX(Z$5:Z6))) | AB6: =IF(T6="","",Z6-AA6) | AC6: =IF(U6="","",IF(U6="Loss",N(AC5)+1,0)) | AE6: =IF(B6="","",IF(AND(M6="Yes",OR(AD6="None",AD6="")),"Yes","No"))
A7: =IF(B7="","",ROW()-4) | C7: =IF(B7="","",INT((B7-Settings!$B$4)/7)+1) | M7: =IF(B7="","",IF(COUNTIF(H7:L7,"Y")=5,"Yes","No")) | Q7: =IF(OR(O7="",P7=""),"",IF(F7="Long",O7+Settings!$B$7*(O7-P7),O7-Settings!$B$7*(P7-O7))) | T7: =IF(OR(R7="",O7="",P7="",O7=P7),"",ROUND(IF(F7="Long",(R7-O7)/(O7-P7),(O7-R7)/(P7-O7)),2)) | U7: =IF(T7="","",IF(T7>=Settings!$B$20,"Win",IF(T7<=-Settings!$B$20,"Loss","BE"))) | V7: =IF(B7="","",Settings!$B$6) | W7: =IF(B7="","",(Settings!$B$5+SUM(X$4:X6))*V7) | X7: =IF(T7="","",ROUND(T7*W7,2)) | Y7: =IF(T7="","",Settings!$B$5+SUM(X$5:X7)) | Z7: =IF(T7="","",SUM(T$5:T7)) | AA7: =IF(T7="","",MAX(0,MAX(Z$5:Z7))) | AB7: =IF(T7="","",Z7-AA7) | AC7: =IF(U7="","",IF(U7="Loss",N(AC6)+1,0)) | AE7: =IF(B7="","",IF(AND(M7="Yes",OR(AD7="None",AD7="")),"Yes","No"))
A8: =IF(B8="","",ROW()-4) | C8: =IF(B8="","",INT((B8-Settings!$B$4)/7)+1) | M8: =IF(B8="","",IF(COUNTIF(H8:L8,"Y")=5,"Yes","No")) | Q8: =IF(OR(O8="",P8=""),"",IF(F8="Long",O8+Settings!$B$7*(O8-P8),O8-Settings!$B$7*(P8-O8))) | T8: =IF(OR(R8="",O8="",P8="",O8=P8),"",ROUND(IF(F8="Long",(R8-O8)/(O8-P8),(O8-R8)/(P8-O8)),2)) | U8: =IF(T8="","",IF(T8>=Settings!$B$20,"Win",IF(T8<=-Settings!$B$20,"Loss","BE"))) | V8: =IF(B8="","",Settings!$B$6) | W8: =IF(B8="","",(Settings!$B$5+SUM(X$4:X7))*V8) | X8: =IF(T8="","",ROUND(T8*W8,2)) | Y8: =IF(T8="","",Settings!$B$5+SUM(X$5:X8)) | Z8: =IF(T8="","",SUM(T$5:T8)) | AA8: =IF(T8="","",MAX(0,MAX(Z$5:Z8))) | AB8: =IF(T8="","",Z8-AA8) | AC8: =IF(U8="","",IF(U8="Loss",N(AC7)+1,0)) | AE8: =IF(B8="","",IF(AND(M8="Yes",OR(AD8="None",AD8="")),"Yes","No"))
A9: =IF(B9="","",ROW()-4) | C9: =IF(B9="","",INT((B9-Settings!$B$4)/7)+1) | M9: =IF(B9="","",IF(COUNTIF(H9:L9,"Y")=5,"Yes","No")) | Q9: =IF(OR(O9="",P9=""),"",IF(F9="Long",O9+Settings!$B$7*(O9-P9),O9-Settings!$B$7*(P9-O9))) | T9: =IF(OR(R9="",O9="",P9="",O9=P9),"",ROUND(IF(F9="Long",(R9-O9)/(O9-P9),(O9-R9)/(P9-O9)),2)) | U9: =IF(T9="","",IF(T9>=Settings!$B$20,"Win",IF(T9<=-Settings!$B$20,"Loss","BE"))) | V9: =IF(B9="","",Settings!$B$6) | W9: =IF(B9="","",(Settings!$B$5+SUM(X$4:X8))*V9) | X9: =IF(T9="","",ROUND(T9*W9,2)) | Y9: =IF(T9="","",Settings!$B$5+SUM(X$5:X9)) | Z9: =IF(T9="","",SUM(T$5:T9)) | AA9: =IF(T9="","",MAX(0,MAX(Z$5:Z9))) | AB9: =IF(T9="","",Z9-AA9) | AC9: =IF(U9="","",IF(U9="Loss",N(AC8)+1,0)) | AE9: =IF(B9="","",IF(AND(M9="Yes",OR(AD9="None",AD9="")),"Yes","No"))
A10: =IF(B10="","",ROW()-4) | C10: =IF(B10="","",INT((B10-Settings!$B$4)/7)+1) | M10: =IF(B10="","",IF(COUNTIF(H10:L10,"Y")=5,"Yes","No")) | Q10: =IF(OR(O10="",P10=""),"",IF(F10="Long",O10+Settings!$B$7*(O10-P10),O10-Settings!$B$7*(P10-O10))) | T10: =IF(OR(R10="",O10="",P10="",O10=P10),"",ROUND(IF(F10="Long",(R10-O10)/(O10-P10),(O10-R10)/(P10-O10)),2)) | U10: =IF(T10="","",IF(T10>=Settings!$B$20,"Win",IF(T10<=-Settings!$B$20,"Loss","BE"))) | V10: =IF(B10="","",Settings!$B$6) | W10: =IF(B10="","",(Settings!$B$5+SUM(X$4:X9))*V10) | X10: =IF(T10="","",ROUND(T10*W10,2)) | Y10: =IF(T10="","",Settings!$B$5+SUM(X$5:X10)) | Z10: =IF(T10="","",SUM(T$5:T10)) | AA10: =IF(T10="","",MAX(0,MAX(Z$5:Z10))) | AB10: =IF(T10="","",Z10-AA10) | AC10: =IF(U10="","",IF(U10="Loss",N(AC9)+1,0)) | AE10: =IF(B10="","",IF(AND(M10="Yes",OR(AD10="None",AD10="")),"Yes","No"))
A11: =IF(B11="","",ROW()-4) | C11: =IF(B11="","",INT((B11-Settings!$B$4)/7)+1) | M11: =IF(B11="","",IF(COUNTIF(H11:L11,"Y")=5,"Yes","No")) | Q11: =IF(OR(O11="",P11=""),"",IF(F11="Long",O11+Settings!$B$7*(O11-P11),O11-Settings!$B$7*(P11-O11))) | T11: =IF(OR(R11="",O11="",P11="",O11=P11),"",ROUND(IF(F11="Long",(R11-O11)/(O11-P11),(O11-R11)/(P11-O11)),2)) | U11: =IF(T11="","",IF(T11>=Settings!$B$20,"Win",IF(T11<=-Settings!$B$20,"Loss","BE"))) | V11: =IF(B11="","",Settings!$B$6) | W11: =IF(B11="","",(Settings!$B$5+SUM(X$4:X10))*V11) | X11: =IF(T11="","",ROUND(T11*W11,2)) | Y11: =IF(T11="","",Settings!$B$5+SUM(X$5:X11)) | Z11: =IF(T11="","",SUM(T$5:T11)) | AA11: =IF(T11="","",MAX(0,MAX(Z$5:Z11))) | AB11: =IF(T11="","",Z11-AA11) | AC11: =IF(U11="","",IF(U11="Loss",N(AC10)+1,0)) | AE11: =IF(B11="","",IF(AND(M11="Yes",OR(AD11="None",AD11="")),"Yes","No"))
A12: =IF(B12="","",ROW()-4) | C12: =IF(B12="","",INT((B12-Settings!$B$4)/7)+1) | M12: =IF(B12="","",IF(COUNTIF(H12:L12,"Y")=5,"Yes","No")) | Q12: =IF(OR(O12="",P12=""),"",IF(F12="Long",O12+Settings!$B$7*(O12-P12),O12-Settings!$B$7*(P12-O12))) | T12: =IF(OR(R12="",O12="",P12="",O12=P12),"",ROUND(IF(F12="Long",(R12-O12)/(O12-P12),(O12-R12)/(P12-O12)),2)) | U12: =IF(T12="","",IF(T12>=Settings!$B$20,"Win",IF(T12<=-Settings!$B$20,"Loss","BE"))) | V12: =IF(B12="","",Settings!$B$6) | W12: =IF(B12="","",(Settings!$B$5+SUM(X$4:X11))*V12) | X12: =IF(T12="","",ROUND(T12*W12,2)) | Y12: =IF(T12="","",Settings!$B$5+SUM(X$5:X12)) | Z12: =IF(T12="","",SUM(T$5:T12)) | AA12: =IF(T12="","",MAX(0,MAX(Z$5:Z12))) | AB12: =IF(T12="","",Z12-AA12) | AC12: =IF(U12="","",IF(U12="Loss",N(AC11)+1,0)) | AE12: =IF(B12="","",IF(AND(M12="Yes",OR(AD12="None",AD12="")),"Yes","No"))
A13: =IF(B13="","",ROW()-4) | C13: =IF(B13="","",INT((B13-Settings!$B$4)/7)+1) | M13: =IF(B13="","",IF(COUNTIF(H13:L13,"Y")=5,"Yes","No")) | Q13: =IF(OR(O13="",P13=""),"",IF(F13="Long",O13+Settings!$B$7*(O13-P13),O13-Settings!$B$7*(P13-O13))) | T13: =IF(OR(R13="",O13="",P13="",O13=P13),"",ROUND(IF(F13="Long",(R13-O13)/(O13-P13),(O13-R13)/(P13-O13)),2)) | U13: =IF(T13="","",IF(T13>=Settings!$B$20,"Win",IF(T13<=-Settings!$B$20,"Loss","BE"))) | V13: =IF(B13="","",Settings!$B$6) | W13: =IF(B13="","",(Settings!$B$5+SUM(X$4:X12))*V13) | X13: =IF(T13="","",ROUND(T13*W13,2)) | Y13: =IF(T13="","",Settings!$B$5+SUM(X$5:X13)) | Z13: =IF(T13="","",SUM(T$5:T13)) | AA13: =IF(T13="","",MAX(0,MAX(Z$5:Z13))) | AB13: =IF(T13="","",Z13-AA13) | AC13: =IF(U13="","",IF(U13="Loss",N(AC12)+1,0)) | AE13: =IF(B13="","",IF(AND(M13="Yes",OR(AD13="None",AD13="")),"Yes","No"))
A14: =IF(B14="","",ROW()-4) | C14: =IF(B14="","",INT((B14-Settings!$B$4)/7)+1) | M14: =IF(B14="","",IF(COUNTIF(H14:L14,"Y")=5,"Yes","No")) | Q14: =IF(OR(O14="",P14=""),"",IF(F14="Long",O14+Settings!$B$7*(O14-P14),O14-Settings!$B$7*(P14-O14))) | T14: =IF(OR(R14="",O14="",P14="",O14=P14),"",ROUND(IF(F14="Long",(R14-O14)/(O14-P14),(O14-R14)/(P14-O14)),2)) | U14: =IF(T14="","",IF(T14>=Settings!$B$20,"Win",IF(T14<=-Settings!$B$20,"Loss","BE"))) | V14: =IF(B14="","",Settings!$B$6) | W14: =IF(B14="","",(Settings!$B$5+SUM(X$4:X13))*V14) | X14: =IF(T14="","",ROUND(T14*W14,2)) | Y14: =IF(T14="","",Settings!$B$5+SUM(X$5:X14)) | Z14: =IF(T14="","",SUM(T$5:T14)) | AA14: =IF(T14="","",MAX(0,MAX(Z$5:Z14))) | AB14: =IF(T14="","",Z14-AA14) | AC14: =IF(U14="","",IF(U14="Loss",N(AC13)+1,0)) | AE14: =IF(B14="","",IF(AND(M14="Yes",OR(AD14="None",AD14="")),"Yes","No"))
A15: =IF(B15="","",ROW()-4) | C15: =IF(B15="","",INT((B15-Settings!$B$4)/7)+1) | M15: =IF(B15="","",IF(COUNTIF(H15:L15,"Y")=5,"Yes","No")) | Q15: =IF(OR(O15="",P15=""),"",IF(F15="Long",O15+Settings!$B$7*(O15-P15),O15-Settings!$B$7*(P15-O15))) | T15: =IF(OR(R15="",O15="",P15="",O15=P15),"",ROUND(IF(F15="Long",(R15-O15)/(O15-P15),(O15-R15)/(P15-O15)),2)) | U15: =IF(T15="","",IF(T15>=Settings!$B$20,"Win",IF(T15<=-Settings!$B$20,"Loss","BE"))) | V15: =IF(B15="","",Settings!$B$6) | W15: =IF(B15="","",(Settings!$B$5+SUM(X$4:X14))*V15) | X15: =IF(T15="","",ROUND(T15*W15,2)) | Y15: =IF(T15="","",Settings!$B$5+SUM(X$5:X15)) | Z15: =IF(T15="","",SUM(T$5:T15)) | AA15: =IF(T15="","",MAX(0,MAX(Z$5:Z15))) | AB15: =IF(T15="","",Z15-AA15) | AC15: =IF(U15="","",IF(U15="Loss",N(AC14)+1,0)) | AE15: =IF(B15="","",IF(AND(M15="Yes",OR(AD15="None",AD15="")),"Yes","No"))
A16: =IF(B16="","",ROW()-4) | C16: =IF(B16="","",INT((B16-Settings!$B$4)/7)+1) | M16: =IF(B16="","",IF(COUNTIF(H16:L16,"Y")=5,"Yes","No")) | Q16: =IF(OR(O16="",P16=""),"",IF(F16="Long",O16+Settings!$B$7*(O16-P16),O16-Settings!$B$7*(P16-O16))) | T16: =IF(OR(R16="",O16="",P16="",O16=P16),"",ROUND(IF(F16="Long",(R16-O16)/(O16-P16),(O16-R16)/(P16-O16)),2)) | U16: =IF(T16="","",IF(T16>=Settings!$B$20,"Win",IF(T16<=-Settings!$B$20,"Loss","BE"))) | V16: =IF(B16="","",Settings!$B$6) | W16: =IF(B16="","",(Settings!$B$5+SUM(X$4:X15))*V16) | X16: =IF(T16="","",ROUND(T16*W16,2)) | Y16: =IF(T16="","",Settings!$B$5+SUM(X$5:X16)) | Z16: =IF(T16="","",SUM(T$5:T16)) | AA16: =IF(T16="","",MAX(0,MAX(Z$5:Z16))) | AB16: =IF(T16="","",Z16-AA16) | AC16: =IF(U16="","",IF(U16="Loss",N(AC15)+1,0)) | AE16: =IF(B16="","",IF(AND(M16="Yes",OR(AD16="None",AD16="")),"Yes","No"))
... A304: =IF(B304="","",ROW()-4) | C304: =IF(B304="","",INT((B304-Settings!$B$4)/7)+1) | M304: =IF(B304="","",IF(COUNTIF(H304:L304,"Y")=5,"Yes","No")) | Q304: =IF(OR(O304="",P304=""),"",IF(F304="Long",O304+Settings!$B$7*(O304-P304),O304-Settings!$B$7*(P304-O304))) | T304: =IF(OR(R304="",O304="",P304="",O304=P304),"",ROUND(IF(F304="Long",(R304-O304)/(O304-P304),(O304-R304)/(P304-O304)),2)) | U304: =IF(T304="","",IF(T304>=Settings!$B$20,"Win",IF(T304<=-Settings!$B$20,"Loss","BE"))) | V304: =IF(B304="","",Settings!$B$6) | W304: =IF(B304="","",(Settings!$B$5+SUM(X$4:X303))*V304) | X304: =IF(T304="","",ROUND(T304*W304,2)) | Y304: =IF(T304="","",Settings!$B$5+SUM(X$5:X304)) | Z304: =IF(T304="","",SUM(T$5:T304)) | AA304: =IF(T304="","",MAX(0,MAX(Z$5:Z304))) | AB304: =IF(T304="","",Z304-AA304) | AC304: =IF(U304="","",IF(U304="Loss",N(AC303)+1,0)) | AE304: =IF(B304="","",IF(AND(M304="Yes",OR(AD304="None",AD304="")),"Yes","No"))

Sheet Daily Log
A1: Daily Log
A2: One row per weekday (12 weeks pre-filled). Mark each session Y/N, even on days with no trades.
A4: Date | B4: Week | C4: London session attended? (Y/N) | D4: New York session attended? (Y/N) | E4: Pre-session prep done? (Y/N) | F4: Trades taken | G4: Day result (R) | H4: Rule breaks | I4: Daily limits respected? (Y/N) | J4: Mood / energy (1-5) | K4: Key lesson of the day
A5: =WORKDAY(Settings!$B$4-1,1) -> 46307 | B5: =INT((A5-Settings!$B$4)/7)+1 -> 1 | F5: =COUNTIF(Journal!$B$5:$B$304,A5) -> 0 | G5: =SUMIFS(Journal!$T$5:$T$304,Journal!$B$5:$B$304,A5) -> 0 | H5: =COUNTIFS(Journal!$B$5:$B$304,A5,Journal!$AE$5:$AE$304,"No") -> 0
A6: =WORKDAY(A5,1) -> 46308 | B6: =INT((A6-Settings!$B$4)/7)+1 -> 1 | F6: =COUNTIF(Journal!$B$5:$B$304,A6) -> 0 | G6: =SUMIFS(Journal!$T$5:$T$304,Journal!$B$5:$B$304,A6) -> 0 | H6: =COUNTIFS(Journal!$B$5:$B$304,A6,Journal!$AE$5:$AE$304,"No") -> 0
A7: =WORKDAY(A6,1) -> 46309 | B7: =INT((A7-Settings!$B$4)/7)+1 -> 1 | F7: =COUNTIF(Journal!$B$5:$B$304,A7) -> 0 | G7: =SUMIFS(Journal!$T$5:$T$304,Journal!$B$5:$B$304,A7) -> 0 | H7: =COUNTIFS(Journal!$B$5:$B$304,A7,Journal!$AE$5:$AE$304,"No") -> 0
A8: =WORKDAY(A7,1) -> 46310 | B8: =INT((A8-Settings!$B$4)/7)+1 -> 1 | F8: =COUNTIF(Journal!$B$5:$B$304,A8) -> 0 | G8: =SUMIFS(Journal!$T$5:$T$304,Journal!$B$5:$B$304,A8) -> 0 | H8: =COUNTIFS(Journal!$B$5:$B$304,A8,Journal!$AE$5:$AE$304,"No") -> 0
A9: =WORKDAY(A8,1) -> 46311 | B9: =INT((A9-Settings!$B$4)/7)+1 -> 1 | F9: =COUNTIF(Journal!$B$5:$B$304,A9) -> 0 | G9: =SUMIFS(Journal!$T$5:$T$304,Journal!$B$5:$B$304,A9) -> 0 | H9: =COUNTIFS(Journal!$B$5:$B$304,A9,Journal!$AE$5:$AE$304,"No") -> 0
A10: =WORKDAY(A9,1) -> 46314 | B10: =INT((A10-Settings!$B$4)/7)+1 -> 2 | F10: =COUNTIF(Journal!$B$5:$B$304,A10) -> 0 | G10: =SUMIFS(Journal!$T$5:$T$304,Journal!$B$5:$B$304,A10) -> 0 | H10: =COUNTIFS(Journal!$B$5:$B$304,A10,Journal!$AE$5:$AE$304,"No") -> 0
A11: =WORKDAY(A10,1) -> 46315 | B11: =INT((A11-Settings!$B$4)/7)+1 -> 2 | F11: =COUNTIF(Journal!$B$5:$B$304,A11) -> 0 | G11: =SUMIFS(Journal!$T$5:$T$304,Journal!$B$5:$B$304,A11) -> 0 | H11: =COUNTIFS(Journal!$B$5:$B$304,A11,Journal!$AE$5:$AE$304,"No") -> 0
A12: =WORKDAY(A11,1) -> 46316 | B12: =INT((A12-Settings!$B$4)/7)+1 -> 2 | F12: =COUNTIF(Journal!$B$5:$B$304,A12) -> 0 | G12: =SUMIFS(Journal!$T$5:$T$304,Journal!$B$5:$B$304,A12) -> 0 | H12: =COUNTIFS(Journal!$B$5:$B$304,A12,Journal!$AE$5:$AE$304,"No") -> 0
A13: =WORKDAY(A12,1) -> 46317 | B13: =INT((A13-Settings!$B$4)/7)+1 -> 2 | F13: =COUNTIF(Journal!$B$5:$B$304,A13) -> 0 | G13: =SUMIFS(Journal!$T$5:$T$304,Journal!$B$5:$B$304,A13) -> 0 | H13: =COUNTIFS(Journal!$B$5:$B$304,A13,Journal!$AE$5:$AE$304,"No") -> 0
A14: =WORKDAY(A13,1) -> 46318 | B14: =INT((A14-Settings!$B$4)/7)+1 -> 2 | F14: =COUNTIF(Journal!$B$5:$B$304,A14) -> 0 | G14: =SUMIFS(Journal!$T$5:$T$304,Journal!$B$5:$B$304,A14) -> 0 | H14: =COUNTIFS(Journal!$B$5:$B$304,A14,Journal!$AE$5:$AE$304,"No") -> 0
A15: =WORKDAY(A14,1) -> 46321 | B15: =INT((A15-Settings!$B$4)/7)+1 -> 3 | F15: =COUNTIF(Journal!$B$5:$B$304,A15) -> 0 | G15: =SUMIFS(Journal!$T$5:$T$304,Journal!$B$5:$B$304,A15) -> 0 | H15: =COUNTIFS(Journal!$B$5:$B$304,A15,Journal!$AE$5:$AE$304,"No") -> 0
A16: =WORKDAY(A15,1) -> 46322 | B16: =INT((A16-Settings!$B$4)/7)+1 -> 3 | F16: =COUNTIF(Journal!$B$5:$B$304,A16) -> 0 | G16: =SUMIFS(Journal!$T$5:$T$304,Journal!$B$5:$B$304,A16) -> 0 | H16: =COUNTIFS(Journal!$B$5:$B$304,A16,Journal!$AE$5:$AE$304,"No") -> 0
A17: =WORKDAY(A16,1) -> 46323 | B17: =INT((A17-Settings!$B$4)/7)+1 -> 3 | F17: =COUNTIF(Journal!$B$5:$B$304,A17) -> 0 | G17: =SUMIFS(Journal!$T$5:$T$304,Journal!$B$5:$B$304,A17) -> 0 | H17: =COUNTIFS(Journal!$B$5:$B$304,A17,Journal!$AE$5:$AE$304,"No") -> 0
... A64: =WORKDAY(A63,1) -> 46388 | B64: =INT((A64-Settings!$B$4)/7)+1 -> 12 | F64: =COUNTIF(Journal!$B$5:$B$304,A64) -> 0 | G64: =SUMIFS(Journal!$T$5:$T$304,Journal!$B$5:$B$304,A64) -> 0 | H64: =COUNTIFS(Journal!$B$5:$B$304,A64,Journal!$AE$5:$AE$304,"No") -> 0

Sheet Weekly Review
A1: Weekly Review
A2: Do this every Friday after the NY session (~20 min). Grey = automatic, yellow = your reflection.
A4: Week | B4: Phase | C4: Mon | D4: Fri | E4: Trades | F4: Wins | G4: Losses | H4: BE | I4: Win rate | J4: Total R | K4: Expectancy (R) | L4: Rule adherence | M4: Session attendance | N4: Cumulative R | O4: Weekly loss limit hit? | P4: Biggest mistake / leak | Q4: What worked | R4: ONE focus for next week | S4: Plan change? (Week 4 only)
A5: 1 | B5: 1 Execution | C5: =Settings!$B$4+(A5-1)*7 -> 46307 | D5: =C5+4 -> 46311 | E5: =COUNTIFS(Journal!$C$5:$C$304,A5,Journal!$T$5:$T$304,">-9999") -> 0 | F5: =COUNTIFS(Journal!$C$5:$C$304,A5,Journal!$U$5:$U$304,"Win") -> 0 | G5: =COUNTIFS(Journal!$C$5:$C$304,A5,Journal!$U$5:$U$304,"Loss") -> 0 | H5: =COUNTIFS(Journal!$C$5:$C$304,A5,Journal!$U$5:$U$304,"BE") -> 0 | I5: =IFERROR(F5/E5,0) -> 0 | J5: =SUMIFS(Journal!$T$5:$T$304,Journal!$C$5:$C$304,A5) -> 0 | K5: =IFERROR(J5/E5,0) -> 0 | L5: =IFERROR(COUNTIFS(Journal!$C$5:$C$304,A5,Journal!$AE$5:$AE$304,"Yes")/COUNTIF(Journal!$C$5:$C$304,A5),0) -> 0 | M5: =IFERROR((COUNTIFS('Daily Log'!$B$5:$B$64,A5,'Daily Log'!$C$5:$C$64,"Y")+COUNTIFS('Daily Log'!$B$5:$B$64,A5,'Daily Log'!$D$5:$D$64,"Y"))/(2*COUNTIF('Daily Log'!$B$5:$B$64,A5)),0) -> 0 | N5: =SUM($J$5:J5) -> 0 | O5: =IF(J5<=Settings!$B$12,"YES - stopped","No") -> No
A6: 2 | B6: 1 Execution | C6: =Settings!$B$4+(A6-1)*7 -> 46314 | D6: =C6+4 -> 46318 | E6: =COUNTIFS(Journal!$C$5:$C$304,A6,Journal!$T$5:$T$304,">-9999") -> 0 | F6: =COUNTIFS(Journal!$C$5:$C$304,A6,Journal!$U$5:$U$304,"Win") -> 0 | G6: =COUNTIFS(Journal!$C$5:$C$304,A6,Journal!$U$5:$U$304,"Loss") -> 0 | H6: =COUNTIFS(Journal!$C$5:$C$304,A6,Journal!$U$5:$U$304,"BE") -> 0 | I6: =IFERROR(F6/E6,0) -> 0 | J6: =SUMIFS(Journal!$T$5:$T$304,Journal!$C$5:$C$304,A6) -> 0 | K6: =IFERROR(J6/E6,0) -> 0 | L6: =IFERROR(COUNTIFS(Journal!$C$5:$C$304,A6,Journal!$AE$5:$AE$304,"Yes")/COUNTIF(Journal!$C$5:$C$304,A6),0) -> 0 | M6: =IFERROR((COUNTIFS('Daily Log'!$B$5:$B$64,A6,'Daily Log'!$C$5:$C$64,"Y")+COUNTIFS('Daily Log'!$B$5:$B$64,A6,'Daily Log'!$D$5:$D$64,"Y"))/(2*COUNTIF('Daily Log'!$B$5:$B$64,A6)),0) -> 0 | N6: =SUM($J$5:J6) -> 0 | O6: =IF(J6<=Settings!$B$12,"YES - stopped","No") -> No
A7: 3 | B7: 2 Data | C7: =Settings!$B$4+(A7-1)*7 -> 46321 | D7: =C7+4 -> 46325 | E7: =COUNTIFS(Journal!$C$5:$C$304,A7,Journal!$T$5:$T$304,">-9999") -> 0 | F7: =COUNTIFS(Journal!$C$5:$C$304,A7,Journal!$U$5:$U$304,"Win") -> 0 | G7: =COUNTIFS(Journal!$C$5:$C$304,A7,Journal!$U$5:$U$304,"Loss") -> 0 | H7: =COUNTIFS(Journal!$C$5:$C$304,A7,Journal!$U$5:$U$304,"BE") -> 0 | I7: =IFERROR(F7/E7,0) -> 0 | J7: =SUMIFS(Journal!$T$5:$T$304,Journal!$C$5:$C$304,A7) -> 0 | K7: =IFERROR(J7/E7,0) -> 0 | L7: =IFERROR(COUNTIFS(Journal!$C$5:$C$304,A7,Journal!$AE$5:$AE$304,"Yes")/COUNTIF(Journal!$C$5:$C$304,A7),0) -> 0 | M7: =IFERROR((COUNTIFS('Daily Log'!$B$5:$B$64,A7,'Daily Log'!$C$5:$C$64,"Y")+COUNTIFS('Daily Log'!$B$5:$B$64,A7,'Daily Log'!$D$5:$D$64,"Y"))/(2*COUNTIF('Daily Log'!$B$5:$B$64,A7)),0) -> 0 | N7: =SUM($J$5:J7) -> 0 | O7: =IF(J7<=Settings!$B$12,"YES - stopped","No") -> No
A8: 4 | B8: 2 Data + review | C8: =Settings!$B$4+(A8-1)*7 -> 46328 | D8: =C8+4 -> 46332 | E8: =COUNTIFS(Journal!$C$5:$C$304,A8,Journal!$T$5:$T$304,">-9999") -> 0 | F8: =COUNTIFS(Journal!$C$5:$C$304,A8,Journal!$U$5:$U$304,"Win") -> 0 | G8: =COUNTIFS(Journal!$C$5:$C$304,A8,Journal!$U$5:$U$304,"Loss") -> 0 | H8: =COUNTIFS(Journal!$C$5:$C$304,A8,Journal!$U$5:$U$304,"BE") -> 0 | I8: =IFERROR(F8/E8,0) -> 0 | J8: =SUMIFS(Journal!$T$5:$T$304,Journal!$C$5:$C$304,A8) -> 0 | K8: =IFERROR(J8/E8,0) -> 0 | L8: =IFERROR(COUNTIFS(Journal!$C$5:$C$304,A8,Journal!$AE$5:$AE$304,"Yes")/COUNTIF(Journal!$C$5:$C$304,A8),0) -> 0 | M8: =IFERROR((COUNTIFS('Daily Log'!$B$5:$B$64,A8,'Daily Log'!$C$5:$C$64,"Y")+COUNTIFS('Daily Log'!$B$5:$B$64,A8,'Daily Log'!$D$5:$D$64,"Y"))/(2*COUNTIF('Daily Log'!$B$5:$B$64,A8)),0) -> 0 | N8: =SUM($J$5:J8) -> 0 | O8: =IF(J8<=Settings!$B$12,"YES - stopped","No") -> No
A9: 5 | B9: 2 Data | C9: =Settings!$B$4+(A9-1)*7 -> 46335 | D9: =C9+4 -> 46339 | E9: =COUNTIFS(Journal!$C$5:$C$304,A9,Journal!$T$5:$T$304,">-9999") -> 0 | F9: =COUNTIFS(Journal!$C$5:$C$304,A9,Journal!$U$5:$U$304,"Win") -> 0 | G9: =COUNTIFS(Journal!$C$5:$C$304,A9,Journal!$U$5:$U$304,"Loss") -> 0 | H9: =COUNTIFS(Journal!$C$5:$C$304,A9,Journal!$U$5:$U$304,"BE") -> 0 | I9: =IFERROR(F9/E9,0) -> 0 | J9: =SUMIFS(Journal!$T$5:$T$304,Journal!$C$5:$C$304,A9) -> 0 | K9: =IFERROR(J9/E9,0) -> 0 | L9: =IFERROR(COUNTIFS(Journal!$C$5:$C$304,A9,Journal!$AE$5:$AE$304,"Yes")/COUNTIF(Journal!$C$5:$C$304,A9),0) -> 0 | M9: =IFERROR((COUNTIFS('Daily Log'!$B$5:$B$64,A9,'Daily Log'!$C$5:$C$64,"Y")+COUNTIFS('Daily Log'!$B$5:$B$64,A9,'Daily Log'!$D$5:$D$64,"Y"))/(2*COUNTIF('Daily Log'!$B$5:$B$64,A9)),0) -> 0 | N9: =SUM($J$5:J9) -> 0 | O9: =IF(J9<=Settings!$B$12,"YES - stopped","No") -> No
A10: 6 | B10: 2 Data | C10: =Settings!$B$4+(A10-1)*7 -> 46342 | D10: =C10+4 -> 46346 | E10: =COUNTIFS(Journal!$C$5:$C$304,A10,Journal!$T$5:$T$304,">-9999") -> 0 | F10: =COUNTIFS(Journal!$C$5:$C$304,A10,Journal!$U$5:$U$304,"Win") -> 0 | G10: =COUNTIFS(Journal!$C$5:$C$304,A10,Journal!$U$5:$U$304,"Loss") -> 0 | H10: =COUNTIFS(Journal!$C$5:$C$304,A10,Journal!$U$5:$U$304,"BE") -> 0 | I10: =IFERROR(F10/E10,0) -> 0 | J10: =SUMIFS(Journal!$T$5:$T$304,Journal!$C$5:$C$304,A10) -> 0 | K10: =IFERROR(J10/E10,0) -> 0 | L10: =IFERROR(COUNTIFS(Journal!$C$5:$C$304,A10,Journal!$AE$5:$AE$304,"Yes")/COUNTIF(Journal!$C$5:$C$304,A10),0) -> 0 | M10: =IFERROR((COUNTIFS('Daily Log'!$B$5:$B$64,A10,'Daily Log'!$C$5:$C$64,"Y")+COUNTIFS('Daily Log'!$B$5:$B$64,A10,'Daily Log'!$D$5:$D$64,"Y"))/(2*COUNTIF('Daily Log'!$B$5:$B$64,A10)),0) -> 0 | N10: =SUM($J$5:J10) -> 0 | O10: =IF(J10<=Settings!$B$12,"YES - stopped","No") -> No
A11: 7 | B11: 3 Proof | C11: =Settings!$B$4+(A11-1)*7 -> 46349 | D11: =C11+4 -> 46353 | E11: =COUNTIFS(Journal!$C$5:$C$304,A11,Journal!$T$5:$T$304,">-9999") -> 0 | F11: =COUNTIFS(Journal!$C$5:$C$304,A11,Journal!$U$5:$U$304,"Win") -> 0 | G11: =COUNTIFS(Journal!$C$5:$C$304,A11,Journal!$U$5:$U$304,"Loss") -> 0 | H11: =COUNTIFS(Journal!$C$5:$C$304,A11,Journal!$U$5:$U$304,"BE") -> 0 | I11: =IFERROR(F11/E11,0) -> 0 | J11: =SUMIFS(Journal!$T$5:$T$304,Journal!$C$5:$C$304,A11) -> 0 | K11: =IFERROR(J11/E11,0) -> 0 | L11: =IFERROR(COUNTIFS(Journal!$C$5:$C$304,A11,Journal!$AE$5:$AE$304,"Yes")/COUNTIF(Journal!$C$5:$C$304,A11),0) -> 0 | M11: =IFERROR((COUNTIFS('Daily Log'!$B$5:$B$64,A11,'Daily Log'!$C$5:$C$64,"Y")+COUNTIFS('Daily Log'!$B$5:$B$64,A11,'Daily Log'!$D$5:$D$64,"Y"))/(2*COUNTIF('Daily Log'!$B$5:$B$64,A11)),0) -> 0 | N11: =SUM($J$5:J11) -> 0 | O11: =IF(J11<=Settings!$B$12,"YES - stopped","No") -> No
A12: 8 | B12: 3 Proof + decide | C12: =Settings!$B$4+(A12-1)*7 -> 46356 | D12: =C12+4 -> 46360 | E12: =COUNTIFS(Journal!$C$5:$C$304,A12,Journal!$T$5:$T$304,">-9999") -> 0 | F12: =COUNTIFS(Journal!$C$5:$C$304,A12,Journal!$U$5:$U$304,"Win") -> 0 | G12: =COUNTIFS(Journal!$C$5:$C$304,A12,Journal!$U$5:$U$304,"Loss") -> 0 | H12: =COUNTIFS(Journal!$C$5:$C$304,A12,Journal!$U$5:$U$304,"BE") -> 0 | I12: =IFERROR(F12/E12,0) -> 0 | J12: =SUMIFS(Journal!$T$5:$T$304,Journal!$C$5:$C$304,A12) -> 0 | K12: =IFERROR(J12/E12,0) -> 0 | L12: =IFERROR(COUNTIFS(Journal!$C$5:$C$304,A12,Journal!$AE$5:$AE$304,"Yes")/COUNTIF(Journal!$C$5:$C$304,A12),0) -> 0 | M12: =IFERROR((COUNTIFS('Daily Log'!$B$5:$B$64,A12,'Daily Log'!$C$5:$C$64,"Y")+COUNTIFS('Daily Log'!$B$5:$B$64,A12,'Daily Log'!$D$5:$D$64,"Y"))/(2*COUNTIF('Daily Log'!$B$5:$B$64,A12)),0) -> 0 | N12: =SUM($J$5:J12) -> 0 | O12: =IF(J12<=Settings!$B$12,"YES - stopped","No") -> No
A13: 9 | B13: Extension | C13: =Settings!$B$4+(A13-1)*7 -> 46363 | D13: =C13+4 -> 46367 | E13: =COUNTIFS(Journal!$C$5:$C$304,A13,Journal!$T$5:$T$304,">-9999") -> 0 | F13: =COUNTIFS(Journal!$C$5:$C$304,A13,Journal!$U$5:$U$304,"Win") -> 0 | G13: =COUNTIFS(Journal!$C$5:$C$304,A13,Journal!$U$5:$U$304,"Loss") -> 0 | H13: =COUNTIFS(Journal!$C$5:$C$304,A13,Journal!$U$5:$U$304,"BE") -> 0 | I13: =IFERROR(F13/E13,0) -> 0 | J13: =SUMIFS(Journal!$T$5:$T$304,Journal!$C$5:$C$304,A13) -> 0 | K13: =IFERROR(J13/E13,0) -> 0 | L13: =IFERROR(COUNTIFS(Journal!$C$5:$C$304,A13,Journal!$AE$5:$AE$304,"Yes")/COUNTIF(Journal!$C$5:$C$304,A13),0) -> 0 | M13: =IFERROR((COUNTIFS('Daily Log'!$B$5:$B$64,A13,'Daily Log'!$C$5:$C$64,"Y")+COUNTIFS('Daily Log'!$B$5:$B$64,A13,'Daily Log'!$D$5:$D$64,"Y"))/(2*COUNTIF('Daily Log'!$B$5:$B$64,A13)),0) -> 0 | N13: =SUM($J$5:J13) -> 0 | O13: =IF(J13<=Settings!$B$12,"YES - stopped","No") -> No
A14: 10 | B14: Extension | C14: =Settings!$B$4+(A14-1)*7 -> 46370 | D14: =C14+4 -> 46374 | E14: =COUNTIFS(Journal!$C$5:$C$304,A14,Journal!$T$5:$T$304,">-9999") -> 0 | F14: =COUNTIFS(Journal!$C$5:$C$304,A14,Journal!$U$5:$U$304,"Win") -> 0 | G14: =COUNTIFS(Journal!$C$5:$C$304,A14,Journal!$U$5:$U$304,"Loss") -> 0 | H14: =COUNTIFS(Journal!$C$5:$C$304,A14,Journal!$U$5:$U$304,"BE") -> 0 | I14: =IFERROR(F14/E14,0) -> 0 | J14: =SUMIFS(Journal!$T$5:$T$304,Journal!$C$5:$C$304,A14) -> 0 | K14: =IFERROR(J14/E14,0) -> 0 | L14: =IFERROR(COUNTIFS(Journal!$C$5:$C$304,A14,Journal!$AE$5:$AE$304,"Yes")/COUNTIF(Journal!$C$5:$C$304,A14),0) -> 0 | M14: =IFERROR((COUNTIFS('Daily Log'!$B$5:$B$64,A14,'Daily Log'!$C$5:$C$64,"Y")+COUNTIFS('Daily Log'!$B$5:$B$64,A14,'Daily Log'!$D$5:$D$64,"Y"))/(2*COUNTIF('Daily Log'!$B$5:$B$64,A14)),0) -> 0 | N14: =SUM($J$5:J14) -> 0 | O14: =IF(J14<=Settings!$B$12,"YES - stopped","No") -> No
A15: 11 | B15: Extension | C15: =Settings!$B$4+(A15-1)*7 -> 46377 | D15: =C15+4 -> 46381 | E15: =COUNTIFS(Journal!$C$5:$C$304,A15,Journal!$T$5:$T$304,">-9999") -> 0 | F15: =COUNTIFS(Journal!$C$5:$C$304,A15,Journal!$U$5:$U$304,"Win") -> 0 | G15: =COUNTIFS(Journal!$C$5:$C$304,A15,Journal!$U$5:$U$304,"Loss") -> 0 | H15: =COUNTIFS(Journal!$C$5:$C$304,A15,Journal!$U$5:$U$304,"BE") -> 0 | I15: =IFERROR(F15/E15,0) -> 0 | J15: =SUMIFS(Journal!$T$5:$T$304,Journal!$C$5:$C$304,A15) -> 0 | K15: =IFERROR(J15/E15,0) -> 0 | L15: =IFERROR(COUNTIFS(Journal!$C$5:$C$304,A15,Journal!$AE$5:$AE$304,"Yes")/COUNTIF(Journal!$C$5:$C$304,A15),0) -> 0 | M15: =IFERROR((COUNTIFS('Daily Log'!$B$5:$B$64,A15,'Daily Log'!$C$5:$C$64,"Y")+COUNTIFS('Daily Log'!$B$5:$B$64,A15,'Daily Log'!$D$5:$D$64,"Y"))/(2*COUNTIF('Daily Log'!$B$5:$B$64,A15)),0) -> 0 | N15: =SUM($J$5:J15) -> 0 | O15: =IF(J15<=Settings!$B$12,"YES - stopped","No") -> No
A16: 12 | B16: Extension | C16: =Settings!$B$4+(A16-1)*7 -> 46384 | D16: =C16+4 -> 46388 | E16: =COUNTIFS(Journal!$C$5:$C$304,A16,Journal!$T$5:$T$304,">-9999") -> 0 | F16: =COUNTIFS(Journal!$C$5:$C$304,A16,Journal!$U$5:$U$304,"Win") -> 0 | G16: =COUNTIFS(Journal!$C$5:$C$304,A16,Journal!$U$5:$U$304,"Loss") -> 0 | H16: =COUNTIFS(Journal!$C$5:$C$304,A16,Journal!$U$5:$U$304,"BE") -> 0 | I16: =IFERROR(F16/E16,0) -> 0 | J16: =SUMIFS(Journal!$T$5:$T$304,Journal!$C$5:$C$304,A16) -> 0 | K16: =IFERROR(J16/E16,0) -> 0 | L16: =IFERROR(COUNTIFS(Journal!$C$5:$C$304,A16,Journal!$AE$5:$AE$304,"Yes")/COUNTIF(Journal!$C$5:$C$304,A16),0) -> 0 | M16: =IFERROR((COUNTIFS('Daily Log'!$B$5:$B$64,A16,'Daily Log'!$C$5:$C$64,"Y")+COUNTIFS('Daily Log'!$B$5:$B$64,A16,'Daily Log'!$D$5:$D$64,"Y"))/(2*COUNTIF('Daily Log'!$B$5:$B$64,A16)),0) -> 0 | N16: =SUM($J$5:J16) -> 0 | O16: =IF(J16<=Settings!$B$12,"YES - stopped","No") -> No
A18: Weeks 9-12 are only used if the go-live criteria are not met after Week 8.

Sheet Settings
A1: Settings & Lists
A2: Yellow cells are yours to change. Everything else in the workbook reads from here.
A3: Parameter | B3: Value | C3: Note | E3: Session | F3: Instrument | G3: Direction | H3: Zone type | I3: Y/N | J3: Exit reason | K3: Mistake | L3: Emotion 1-5
A4: Practice start date (Monday) | B4: 46307 | C4: Week 1 starts here. Change if you start later. | E4: London | F4: XAUUSD | G4: Long | H4: Prev Day High | I4: Y | J4: Target (3R) | K4: None | L4: 1
A5: Starting demo balance ($) | B5: 1000 | C5: Set to your MT5 demo balance. Stats are tracked in R, so the size doesn't matter. | E5: New York | F5: US500 | G5: Short | H5: Prev Day Low | I5: N | J5: Stop loss | K5: Entered before trigger | L5: 2
A6: Risk per trade (% of balance) | B6: 0.005 | C6: 0.5% per trade. | H6: Session High | J6: Break-even | K6: Level not pre-marked | L6: 3
A7: Profit target (R multiple) | B7: 3 | C7: Fixed 1:3 risk-reward, as in the video. | H7: Session Low | J7: Time stop | K7: Moved stop further | L7: 4
A8: Move stop to break-even at (R) | B8: 1.5 | C8: When price reaches +1.5R, move stop to entry. | H8: Clustered S/R | J8: Manual (rule break) | K8: Closed early (fear) | L8: 5
A9: Max trades per session | B9: 2 | H9: Round number | K9: Chased / FOMO
A10: Max trades per day | B10: 3 | K10: Outside session window
A11: Stop for the day after N losses | B11: 2 | K11: Over max trades
A12: Weekly loss limit (R) | B12: -5 | C12: Hit this = no more trades that week; do the review instead. | K12: Revenge trade
A13: Go-live: minimum closed trades | B13: 40 | C13: Fewer trades than this = not enough evidence yet. | K13: Traded through news
A14: Go-live: minimum rule adherence | B14: 0.9 | C14: Share of trades with all 5 checks met and no mistake. | K14: Wrong position size
A15: Go-live: minimum expectancy (R/trade) | B15: 0.25 | C15: Average R per trade.
A16: Go-live: minimum profit factor | B16: 1.3 | C16: Gross R won / gross R lost. | L16: Emotion scale: 1 = calm and focused, 3 = slightly tense, 5 = anxious, excited or angry (5 = skip the session).
A17: Go-live: max drawdown allowed (R) | B17: 10 | C17: Largest peak-to-trough fall in cumulative R.
A18: Go-live: minimum session attendance | B18: 0.9 | C18: Sessions attended / sessions available (from Daily Log).
A19: Current plan version | B19: v1.0 | C19: Change only at the Week 4 review (becomes v1.1).
A20: Win/Loss threshold (R) | B20: 0.1 | C20: Results between -0.1R and +0.1R count as break-even.
A23: Position size calculator
A24: Current balance ($) | B24: =Settings!B5+SUM(Journal!$X$5:$X$304) -> 1000 | C24: Automatic: start balance + all closed P&L.
A25: Risk per trade ($) | B25: =B24*Settings!B6 -> 5
A26: Stop distance (price units) | B26: 3.5 | C26: Example: gold entry 2650.00, stop 2653.50 = 3.50
A27: $ value of a 1.00 price move for 1.00 lot | B27: 100 | C27: Check your broker's MT5 contract spec. Typical: XAUUSD = $100; US500 is often $1 to $10, it varies by broker.
A28: Lot size to use | B28: =IFERROR(ROUNDDOWN(B25/(B26*B27),2),0) -> 0.01 | C28: Rounded down to 0.01 lots. If 0.00, the stop is too wide for your risk, so skip the trade.
